2021-09-04 14:19:39 ERROR (Recorder) [homeassistant.components.recorder.util] The database at //config/home-assistant_v2.db is corrupt or malformed.
Traceback (most recent call last):
  File "/usr/src/homeassistant/homeassistant/components/recorder/util.py", line 163, in validate_sqlite_database
    run_checks_on_open_db(dbpath, conn.cursor(), db_integrity_check)
  File "/usr/src/homeassistant/homeassistant/components/recorder/util.py", line 174, in run_checks_on_open_db
    if basic_sanity_check(cursor) and last_run_was_recently_clean(cursor):
  File "/usr/src/homeassistant/homeassistant/components/recorder/util.py", line 152, in basic_sanity_check
    cursor.execute(f"SELECT * FROM {table} LIMIT 1;")  # sec: not injection
sqlite3.OperationalError: no such table: events
2021-09-04 14:19:39 ERROR (Recorder) [homeassistant.components.recorder.util] The system will rename the corrupt database file //config/home-assistant_v2.db to //config/home-assistant_v2.db.corrupt.2021-09-04T19:19:39.533624+00:00 in order to allow startup to proceed
